Workbook

Sheet 台中
A1: 台中
A2: DataTime | B2: Dry Bulb | C2: RelativeHumidity | D2: Wet Bulb | E2: Dry Bulb2 | F2: Dry Bulb3
A3: 2025-01-06T01:00:00+08:00 | B3: 17.7 | C3: 65 | D3: =B3*ATAN(0.151977*(C3+8.313659)^0.5)+ATAN(B3+C3)-ATAN(C3-1.676331)+0.00391838*C3^1.5*ATAN(0.023101*C3)-4.686035 -> 13.542426 | E3: =VALUE(B3) -> 17.7 | F3: =_xlfn.NUMBERVALUE(C_B0024_002[[#This Row],[Wet Bulb]]) -> 13.542426
A4: 2025-01-06T02:00:00+08:00 | B4: 16.3 | C4: 76 | D4: =B4*ATAN(0.151977*(C4+8.313659)^0.5)+ATAN(B4+C4)-ATAN(C4-1.676331)+0.00391838*C4^1.5*ATAN(0.023101*C4)-4.686035 -> 13.519454 | E4: =VALUE(B4) -> 16.3 | F4: =_xlfn.NUMBERVALUE(C_B0024_002[[#This Row],[Wet Bulb]]) -> 13.519454
A5: 2025-01-06T03:00:00+08:00 | B5: 16.2 | C5: 77 | D5: =B5*ATAN(0.151977*(C5+8.313659)^0.5)+ATAN(B5+C5)-ATAN(C5-1.676331)+0.00391838*C5^1.5*ATAN(0.023101*C5)-4.686035 -> 13.538622 | E5: =VALUE(B5) -> 16.2 | F5: =_xlfn.NUMBERVALUE(C_B0024_002[[#This Row],[Wet Bulb]]) -> 13.538622
A6: 2025-01-06T04:00:00+08:00 | B6: 16.0 | C6: 78 | D6: =B6*ATAN(0.151977*(C6+8.313659)^0.5)+ATAN(B6+C6)-ATAN(C6-1.676331)+0.00391838*C6^1.5*ATAN(0.023101*C6)-4.686035 -> 13.461796 | E6: =VALUE(B6) -> 16 | F6: =_xlfn.NUMBERVALUE(C_B0024_002[[#This Row],[Wet Bulb]]) -> 13.461796
A7: 2025-01-06T05:00:00+08:00 | B7: 15.8 | C7: 78 | D7: =B7*ATAN(0.151977*(C7+8.313659)^0.5)+ATAN(B7+C7)-ATAN(C7-1.676331)+0.00391838*C7^1.5*ATAN(0.023101*C7)-4.686035 -> 13.270862 | E7: =VALUE(B7) -> 15.8 | F7: =_xlfn.NUMBERVALUE(C_B0024_002[[#This Row],[Wet Bulb]]) -> 13.270862
A8: 2025-01-06T06:00:00+08:00 | B8: 15.5 | C8: 78 | D8: =B8*ATAN(0.151977*(C8+8.313659)^0.5)+ATAN(B8+C8)-ATAN(C8-1.676331)+0.00391838*C8^1.5*ATAN(0.023101*C8)-4.686035 -> 12.98446 | E8: =VALUE(B8) -> 15.5 | F8: =_xlfn.NUMBERVALUE(C_B0024_002[[#This Row],[Wet Bulb]]) -> 12.98446
A9: 2025-01-06T07:00:00+08:00 | B9: 14.8 | C9: 80 | D9: =B9*ATAN(0.151977*(C9+8.313659)^0.5)+ATAN(B9+C9)-ATAN(C9-1.676331)+0.00391838*C9^1.5*ATAN(0.023101*C9)-4.686035 -> 12.536976 | E9: =VALUE(B9) -> 14.8 | F9: =_xlfn.NUMBERVALUE(C_B0024_002[[#This Row],[Wet Bulb]]) -> 12.536976
A10: 2025-01-06T08:00:00+08:00 | B10: 16.1 | C10: 73 | D10: =B10*ATAN(0.151977*(C10+8.313659)^0.5)+ATAN(B10+C10)-ATAN(C10-1.676331)+0.00391838*C10^1.5*ATAN(0.023101*C10)-4.686035 -> 12.988322 | E10: =VALUE(B10) -> 16.1 | F10: =_xlfn.NUMBERVALUE(C_B0024_002[[#This Row],[Wet Bulb]]) -> 12.988322
A11: 2025-01-06T09:00:00+08:00 | B11: 18.5 | C11: 63 | D11: =B11*ATAN(0.151977*(C11+8.313659)^0.5)+ATAN(B11+C11)-ATAN(C11-1.676331)+0.00391838*C11^1.5*ATAN(0.023101*C11)-4.686035 -> 14.030509 | E11: =VALUE(B11) -> 18.5 | F11: =_xlfn.NUMBERVALUE(C_B0024_002[[#This Row],[Wet Bulb]]) -> 14.030509
A12: 2025-01-06T10:00:00+08:00 | B12: 19.9 | C12: 58 | D12: =B12*ATAN(0.151977*(C12+8.313659)^0.5)+ATAN(B12+C12)-ATAN(C12-1.676331)+0.00391838*C12^1.5*ATAN(0.023101*C12)-4.686035 -> 14.662502 | E12: =VALUE(B12) -> 19.9 | F12: =_xlfn.NUMBERVALUE(C_B0024_002[[#This Row],[Wet Bulb]]) -> 14.662502
A13: 2025-01-06T11:00:00+08:00 | B13: 20.9 | C13: 52 | D13: =B13*ATAN(0.151977*(C13+8.313659)^0.5)+ATAN(B13+C13)-ATAN(C13-1.676331)+0.00391838*C13^1.5*ATAN(0.023101*C13)-4.686035 -> 14.747131 | E13: =VALUE(B13) -> 20.9 | F13: =_xlfn.NUMBERVALUE(C_B0024_002[[#This Row],[Wet Bulb]]) -> 14.747131
A14: 2025-01-06T12:00:00+08:00 | B14: 21.7 | C14: 48 | D14: =B14*ATAN(0.151977*(C14+8.313659)^0.5)+ATAN(B14+C14)-ATAN(C14-1.676331)+0.00391838*C14^1.5*ATAN(0.023101*C14)-4.686035 -> 14.877033 | E14: =VALUE(B14) -> 21.7 | F14: =_xlfn.NUMBERVALUE(C_B0024_002[[#This Row],[Wet Bulb]]) -> 14.877033
... A8762: 2026-01-06T00:00:00+08:00 | B8762: 15.3 | C8762: 77 | D8762: =B8762*ATAN(0.151977*(C8762+8.313659)^0.5)+ATAN(B8762+C8762)-ATAN(C8762-1.676331)+0.00391838*C8762^1.5*ATAN(0.023101*C8762)-4.686035 -> 12.681889 | E8762: =VALUE(B8762) -> 15.3 | F8762: =_xlfn.NUMBERVALUE(C_B0024_002[[#This Row],[Wet Bulb]]) -> 12.681889
E8763: =VALUE(B8763) -> 0 | F8763: =_xlfn.NUMBERVALUE(C_B0024_002[[#This Row],[Wet Bulb]]) -> 0
E8764: =VALUE(B8764) -> 0 | F8764: =_xlfn.NUMBERVALUE(C_B0024_002[[#This Row],[Wet Bulb]]) -> 0
E8765: =VALUE(B8765) -> 0 | F8765: =_xlfn.NUMBERVALUE(C_B0024_002[[#This Row],[Wet Bulb]]) -> 0
E8766: =VALUE(B8766) -> 0 | F8766: =_xlfn.NUMBERVALUE(C_B0024_002[[#This Row],[Wet Bulb]]) -> 0
E8767: =VALUE(B8767) -> 0 | F8767: =_xlfn.NUMBERVALUE(C_B0024_002[[#This Row],[Wet Bulb]]) -> 0
E8768: =VALUE(B8768) -> 0 | F8768: =_xlfn.NUMBERVALUE(C_B0024_002[[#This Row],[Wet Bulb]]) -> 0
E8769: =VALUE(B8769) -> 0 | F8769: =_xlfn.NUMBERVALUE(C_B0024_002[[#This Row],[Wet Bulb]]) -> 0
E8770: =VALUE(B8770) -> 0 | F8770: =_xlfn.NUMBERVALUE(C_B0024_002[[#This Row],[Wet Bulb]]) -> 0
E8771: =VALUE(B8771) -> 0 | F8771: =_xlfn.NUMBERVALUE(C_B0024_002[[#This Row],[Wet Bulb]]) -> 0
E8772: =VALUE(B8772) -> 0 | F8772: =_xlfn.NUMBERVALUE(C_B0024_002[[#This Row],[Wet Bulb]]) -> 0
E8773: =VALUE(B8773) -> 0 | F8773: =_xlfn.NUMBERVALUE(C_B0024_002[[#This Row],[Wet Bulb]]) -> 0
E8774: =VALUE(B8774) -> 0 | F8774: =_xlfn.NUMBERVALUE(C_B0024_002[[#This Row],[Wet Bulb]]) -> 0
... E8786: =VALUE(B8786) -> 0 | F8786: =_xlfn.NUMBERVALUE(C_B0024_002[[#This Row],[Wet Bulb]]) -> 0

Sheet 濕球時數統計
A2: 29 | B2: {=SUMPRODUCT((C_B0024_002[Wet Bulb]>=A2-0.5)*(C_B0024_002[Wet Bulb]<A2+0.5))} -> 0
A3: 28 | B3: {=SUMPRODUCT((C_B0024_002[Wet Bulb]>=A3-0.5)*(C_B0024_002[Wet Bulb]<A3+0.5))} -> 72
A4: 27 | B4: {=SUMPRODUCT((C_B0024_002[Wet Bulb]>=A4-0.5)*(C_B0024_002[Wet Bulb]<A4+0.5))} -> 445
A5: 26 | B5: {=SUMPRODUCT((C_B0024_002[Wet Bulb]>=A5-0.5)*(C_B0024_002[Wet Bulb]<A5+0.5))} -> 1106
A6: 25 | B6: {=SUMPRODUCT((C_B0024_002[Wet Bulb]>=A6-0.5)*(C_B0024_002[Wet Bulb]<A6+0.5))} -> 1245
A7: 24 | B7: {=SUMPRODUCT((C_B0024_002[Wet Bulb]>=A7-0.5)*(C_B0024_002[Wet Bulb]<A7+0.5))} -> 926
A8: 23 | B8: {=SUMPRODUCT((C_B0024_002[Wet Bulb]>=A8-0.5)*(C_B0024_002[Wet Bulb]<A8+0.5))} -> 487
A9: 22 | B9: {=SUMPRODUCT((C_B0024_002[Wet Bulb]>=A9-0.5)*(C_B0024_002[Wet Bulb]<A9+0.5))} -> 449
A10: 21 | B10: {=SUMPRODUCT((C_B0024_002[Wet Bulb]>=A10-0.5)*(C_B0024_002[Wet Bulb]<A10+0.5))} -> 379
A11: 20 | B11: {=SUMPRODUCT((C_B0024_002[Wet Bulb]>=A11-0.5)*(C_B0024_002[Wet Bulb]<A11+0.5))} -> 335
A12: 19 | B12: {=SUMPRODUCT((C_B0024_002[Wet Bulb]>=A12-0.5)*(C_B0024_002[Wet Bulb]<A12+0.5))} -> 373
A13: 18 | B13: {=SUMPRODUCT((C_B0024_002[Wet Bulb]>=A13-0.5)*(C_B0024_002[Wet Bulb]<A13+0.5))} -> 288
... A29: 2 | B29: {=SUMPRODUCT((C_B0024_002[Wet Bulb]>=A29-0.5)*(C_B0024_002[Wet Bulb]<A29+0.5))} -> 0
B31: =SUM(B2:B29) -> 8760

Sheet 乾球時數統計 
A1: 44 | B1: {=SUMPRODUCT((台中!E3:E8762>=A1-0.5)*(台中!E3:E8762<A1+0.5))} -> 0
A2: 43 | B2: {=SUMPRODUCT((台中!E3:E8762>=A2-0.5)*(台中!E3:E8762<A2+0.5))} -> 0
A3: 42 | B3: {=SUMPRODUCT((台中!E3:E8762>=A3-0.5)*(台中!E3:E8762<A3+0.5))} -> 0
A4: 41 | B4: {=SUMPRODUCT((台中!E3:E8762>=A4-0.5)*(台中!E3:E8762<A4+0.5))} -> 0
A5: 40 | B5: {=SUMPRODUCT((台中!E3:E8762>=A5-0.5)*(台中!E3:E8762<A5+0.5))} -> 0
A6: 39 | B6: {=SUMPRODUCT((台中!E3:E8762>=A6-0.5)*(台中!E3:E8762<A6+0.5))} -> 0
A7: 38 | B7: {=SUMPRODUCT((台中!E3:E8762>=A7-0.5)*(台中!E3:E8762<A7+0.5))} -> 0
A8: 37 | B8: {=SUMPRODUCT((台中!E3:E8762>=A8-0.5)*(台中!E3:E8762<A8+0.5))} -> 0
A9: 36 | B9: {=SUMPRODUCT((台中!E3:E8762>=A9-0.5)*(台中!E3:E8762<A9+0.5))} -> 1
A10: 35 | B10: {=SUMPRODUCT((台中!E3:E8762>=A10-0.5)*(台中!E3:E8762<A10+0.5))} -> 6
A11: 34 | B11: {=SUMPRODUCT((台中!E3:E8762>=A11-0.5)*(台中!E3:E8762<A11+0.5))} -> 44
A12: 33 | B12: {=SUMPRODUCT((台中!E3:E8762>=A12-0.5)*(台中!E3:E8762<A12+0.5))} -> 242
A13: 32 | B13: {=SUMPRODUCT((台中!E3:E8762>=A13-0.5)*(台中!E3:E8762<A13+0.5))} -> 400
A14: 31 | B14: {=SUMPRODUCT((台中!E3:E8762>=A14-0.5)*(台中!E3:E8762<A14+0.5))} -> 397
A15: 30 | B15: {=SUMPRODUCT((台中!E3:E8762>=A15-0.5)*(台中!E3:E8762<A15+0.5))} -> 430
A16: 29 | B16: {=SUMPRODUCT((台中!E3:E8762>=A16-0.5)*(台中!E3:E8762<A16+0.5))} -> 635
A17: 28 | B17: {=SUMPRODUCT((台中!E3:E8762>=A17-0.5)*(台中!E3:E8762<A17+0.5))} -> 717
A18: 27 | B18: {=SUMPRODUCT((台中!E3:E8762>=A18-0.5)*(台中!E3:E8762<A18+0.5))} -> 691
A19: 26 | B19: {=SUMPRODUCT((台中!E3:E8762>=A19-0.5)*(台中!E3:E8762<A19+0.5))} -> 680
A20: 25 | B20: {=SUMPRODUCT((台中!E3:E8762>=A20-0.5)*(台中!E3:E8762<A20+0.5))} -> 627
A21: 24 | B21: {=SUMPRODUCT((台中!E3:E8762>=A21-0.5)*(台中!E3:E8762<A21+0.5))} -> 458
A22: 23 | B22: {=SUMPRODUCT((台中!E3:E8762>=A22-0.5)*(台中!E3:E8762<A22+0.5))} -> 347
A23: 22 | B23: {=SUMPRODUCT((台中!E3:E8762>=A23-0.5)*(台中!E3:E8762<A23+0.5))} -> 335
A24: 21 | B24: {=SUMPRODUCT((台中!E3:E8762>=A24-0.5)*(台中!E3:E8762<A24+0.5))} -> 335
A25: 20 | B25: {=SUMPRODUCT((台中!E3:E8762>=A25-0.5)*(台中!E3:E8762<A25+0.5))} -> 281
A26: 19 | B26: {=SUMPRODUCT((台中!E3:E8762>=A26-0.5)*(台中!E3:E8762<A26+0.5))} -> 321
A27: 18 | B27: {=SUMPRODUCT((台中!E3:E8762>=A27-0.5)*(台中!E3:E8762<A27+0.5))} -> 348
A28: 17 | B28: {=SUMPRODUCT((台中!E3:E8762>=A28-0.5)*(台中!E3:E8762<A28+0.5))} -> 380
A29: 16 | B29: {=SUMPRODUCT((台中!E3:E8762>=A29-0.5)*(台中!E3:E8762<A29+0.5))} -> 338
A30: 15 | B30: {=SUMPRODUCT((台中!E3:E8762>=A30-0.5)*(台中!E3:E8762<A30+0.5))} -> 279
A31: 14 | B31: {=SUMPRODUCT((台中!E3:E8762>=A31-0.5)*(台中!E3:E8762<A31+0.5))} -> 165
A32: 13 | B32: {=SUMPRODUCT((台中!E3:E8762>=A32-0.5)*(台中!E3:E8762<A32+0.5))} -> 133
A33: 12 | B33: {=SUMPRODUCT((台中!E3:E8762>=A33-0.5)*(台中!E3:E8762<A33+0.5))} -> 109
A34: 11 | B34: {=SUMPRODUCT((台中!E3:E8762>=A34-0.5)*(台中!E3:E8762<A34+0.5))} -> 32
A35: 10 | B35: {=SUMPRODUCT((台中!E3:E8762>=A35-0.5)*(台中!E3:E8762<A35+0.5))} -> 23
A36: 9 | B36: {=SUMPRODUCT((台中!E3:E8762>=A36-0.5)*(台中!E3:E8762<A36+0.5))} -> 5
A37: 8 | B37: {=SUMPRODUCT((台中!E3:E8762>=A37-0.5)*(台中!E3:E8762<A37+0.5))} -> 1
A38: 7 | B38: {=SUMPRODUCT((台中!E3:E8762>=A38-0.5)*(台中!E3:E8762<A38+0.5))} -> 0
A39: 6 | B39: {=SUMPRODUCT((台中!E3:E8762>=A39-0.5)*(台中!E3:E8762<A39+0.5))} -> 0
A40: 5 | B40: {=SUMPRODUCT((台中!E3:E8762>=A40-0.5)*(台中!E3:E8762<A40+0.5))} -> 0
...
